<?xml version="1.0" ?>
<robot name="panda" xmlns:xacro="http://www.ros.org/wiki/xacro">
  <!-- Define gripper links -->
  <link name="world"></link>
  
  <!-- Define X-axis link -->
  <joint name="x_axis" type="prismatic">
    <parent link="world"/>
    <child link="x_link"/>
    <axis xyz="1 0 0"/>
    <limit effort="1" lower="-10" upper="10" velocity="1"/>
  </joint>
  <link name="x_link">
    <inertial>
        <origin rpy="0 0 0" xyz="0 0 0"/>
        <mass value="1.2"/>
        <inertia ixx="1" ixy="0" ixz="0" iyy="1" iyz="0" izz="1"/>
    </inertial>
  </link>

  <!-- Define Y-axis link -->
  <joint name="y_axis" type="prismatic">
    <parent link="x_link"/>
    <child link="y_link"/>
    <axis xyz="0 1 0"/>
    <limit effort="1" lower="-10" upper="10" velocity="1"/>
  </joint>
  <link name="y_link">
    <inertial>
        <origin rpy="0 0 0" xyz="0 0 0"/>
        <mass value="1.2"/>
        <inertia ixx="1" ixy="0" ixz="0" iyy="1" iyz="0" izz="1"/>
    </inertial>
  </link>

  <!-- Define Z-axis link -->
  <joint name="z_axis" type="prismatic">
    <parent link="y_link"/>
    <child link="z_link"/>
    <axis xyz="0 0 1"/>
    <limit effort="1" lower="-10" upper="10" velocity="1"/>
  </joint>
  <link name="z_link">
    <inertial>
        <origin rpy="0 0 0" xyz="0 0 0"/>
        <mass value="1.2"/>
        <inertia ixx="1" ixy="0" ixz="0" iyy="1" iyz="0" izz="1"/>
    </inertial>
  </link>

  <!-- Rotate around z-axis -->
  <joint name="panda_rot_z_joint" type="revolute">
    <parent link="z_link"/>
    <child link="z_rot_link"/>
    <axis xyz="0 0 1"/>
    <origin rpy="3.14159265359 0 0" xyz="0 0 0"/>
    <limit effort="1" lower="-1" upper="1" velocity="1"/>
  </joint>
  <link name="z_rot_link">
    <inertial>
        <origin rpy="0 0 0" xyz="0 0 0"/>
        <mass value="1.2"/>
        <inertia ixx="1" ixy="0" ixz="0" iyy="1" iyz="0" izz="1"/>
    </inertial>
  </link>

  <!-- Rotate around y-axis -->
  <joint name="panda_rot_y_joint" type="revolute">
    <parent link="z_rot_link"/>
    <child link="y_rot_link"/>
    <axis xyz="0 1 0"/>
    <origin rpy="0 0 0" xyz="0 0 0"/>
    <limit effort="1" lower="-1" upper="1" velocity="1"/>
  </joint>
  <link name="y_rot_link">
    <inertial>
        <origin rpy="0 0 0" xyz="0 0 0"/>
        <mass value="1.2"/>
        <inertia ixx="1" ixy="0" ixz="0" iyy="1" iyz="0" izz="1"/>
    </inertial>
  </link>

  <!-- Connect the gripper-->
  <joint name="panda_gripper_joint" type="fixed">
    <parent link="y_rot_link"/>
    <child link="panda_hand"/>
    <origin rpy="0 0 0" xyz="0 0 0.1"/>
  </joint>
  <link name="panda_hand">
  	<inertial>
      <origin rpy="0 0 0" xyz="0 0 0.04"/>
       <mass value=".81"/>
       <inertia ixx="0.1" ixy="0" ixz="0" iyy="0.1" iyz="0" izz="0.1"/>
    </inertial>
    <visual>
      <geometry>
        <mesh filename="package://meshes/visual/hand.obj"/>
      </geometry>
      <material name="panda_white"/>
    </visual>
    <collision>
      <geometry>
        <mesh filename="package://meshes/collision/hand.obj"/>
      </geometry>
      <material name="panda_white"/>
    </collision>
  </link>

  <link name="panda_leftfinger">
       <contact>
      <friction_anchor/>
      <stiffness value="30000.0"/>
      <damping value="1000.0"/>
      <spinning_friction value="0.1"/>
      <lateral_friction value="1.0"/>
    </contact>
  	<inertial>
      <origin rpy="0 0 0" xyz="0 0.01 0.02"/>
       <mass value="0.1"/>
       <inertia ixx="0.1" ixy="0" ixz="0" iyy="0.1" iyz="0" izz="0.1"/>
    </inertial>
    <visual>
      <geometry>
        <mesh filename="package://meshes/visual/finger.obj"/>
      </geometry>
      <material name="panda_white"/>
    </visual>
    <collision>
      <geometry>
        <box size="0.01 0.01 0.1"/>
      </geometry>
      <material name="panda_white"/>
    </collision>
  </link>
  <link name="panda_rightfinger">
        <contact>
      <friction_anchor/>
      <stiffness value="30000.0"/>
      <damping value="1000.0"/>
      <spinning_friction value="0.1"/>
      <lateral_friction value="1.0"/>
    </contact>

  	<inertial>
      <origin rpy="0 0 0" xyz="0 -0.01 0.02"/>
       <mass value="0.1"/>
       <inertia ixx="0.1" ixy="0" ixz="0" iyy="0.1" iyz="0" izz="0.1"/>
    </inertial>
    <visual>
      <origin rpy="0 0 3.14159265359" xyz="0 0 0"/>
      <geometry>
        <mesh filename="package://meshes/visual/finger.obj"/>
      </geometry>
      <material name="panda_white"/>
    </visual>
    <collision>
      <origin rpy="0 0 3.14159265359" xyz="0 0 0"/>
      <geometry>
        <box size="0.01 0.01 0.1"/>
      </geometry>
      <material name="panda_white"/>
    </collision>
  </link>
  <joint name="panda_finger_joint1" type="prismatic">
    <parent link="panda_hand"/>
    <child link="panda_leftfinger"/>
    <origin rpy="0 0 0" xyz="0 0 0.0584"/>
    <axis xyz="0 1 0"/>
    <limit effort="20" lower="0.0" upper="0.04" velocity="0.2"/>
  </joint>
  <joint name="panda_finger_joint2" type="prismatic">
    <parent link="panda_hand"/>
    <child link="panda_rightfinger"/>
    <origin rpy="0 0 0" xyz="0 0 0.0584"/>
    <axis xyz="0 -1 0"/>
    <limit effort="20" lower="0.0" upper="0.04" velocity="0.2"/>
    <mimic joint="panda_finger_joint1"/>
  </joint>
   <link name="panda_grasptarget">
 <inertial>
      <origin rpy="0 0 0" xyz="0 0 0"/>
       <mass value="0.0"/>
       <inertia ixx="0.1" ixy="0" ixz="0" iyy="0.1" iyz="0" izz="0.1"/>
    </inertial>
   </link>
   <joint name="panda_grasptarget_hand" type="fixed">
    <parent link="panda_hand"/>
    <child link="panda_grasptarget"/>
    <origin rpy="0 0 0" xyz="0 0 0.105"/>
  </joint>

  <!-- Define the black material -->
  <material name="black">
    <color rgba="0 0 0 1"/>
  </material>

  <!-- Define the white material -->
  <material name="white">
    <color rgba="1 1 1 1"/>
  </material>

  <!--Camera link--> 
  <link name="camera_link">
  <inertial>
    <origin rpy="0 0 0" xyz="0 0 0"/>
    <mass value="0.1"/>
    <inertia ixx="0.0001" ixy="0.0" ixz="0.0" iyy="0.0001" iyz="0.0" izz="0.0001"/>
  </inertial>
  <visual>
      <origin xyz="0 0 0" rpy="0 0 0"/>
      <geometry>
        <box size="0.02 0.05 0.02"/>
      </geometry>
      <material name="black"/>
  </visual>
  </link>

  <!--Camera Lense Link-->
  <link name="camera_lense">
  <inertial>
    <origin rpy="0 0 0" xyz="0 0 0"/>
    <mass value="0.1"/>
    <inertia ixx="0.0001" ixy="0.0" ixz="0.0" iyy="0.0001" iyz="0.0" izz="0.0001"/>
  </inertial>
  <visual>
      <origin xyz="0 0 0" rpy="0 0 0"/>
      <geometry>
        <cylinder length="0.001" radius="0.005"/>
      </geometry>
      <material name="white"/>
  </visual>
  </link>

  <!--Camera Lense Joint-->
  <joint name="camera_lense_joint" type="fixed">
    <parent link="camera_link"/>
    <child link="camera_lense"/>
    <origin rpy="0 0 0" xyz="0 0 0.01"/>
  </joint>

  <!--Camera Mount Joint-->
  <joint name="camera_mount_joint" type="fixed">
    <parent link="panda_hand"/>
    <child link="camera_link"/>
    <origin rpy="0 0 0" xyz="0.03 0 0.05"/>
  </joint>
  
</robot>